Workbook

Sheet Dashboard
B1: Yarn Supply Chain: Shipment Delays and Expedite Decisions
B2: Surat yarn network · synthetic dataset of 1,000 shipments booked Jan–Oct 2025 · every figure is a live formula over the Clean, Analysis and Model sheets
B4: Shipments | D4: Arrived late | F4: Avg delay when late | H4: Shipping spend | J4: Expected stockout cost if never expedited | L4: Smart-rule saving | N4: Late-rate gap, best vs worst carrier
B5: =Analysis!B11 -> 1000 | D5: =Analysis!C11 -> 0.745 | F5: =TEXT(Analysis!E11,"0.0")&" days" -> 3.4 days | H5: =SUM(Clean!$AD$2:$AD$1001) -> 5250544.5 | J5: =Model!B15 -> 7572796.1 | L5: =Model!D17 -> 4837741.5 | N5: =Analysis!C12 -> 0.053662093
B37: Lanes: late % by route | I37: What this shows
B38: Route | E38: Shipments | F38: Late % | G38: Avg delay | I38: ="Roughly "&TEXT(Analysis!C11,"0%")&" of shipments arrive late, on every carrier." -> Roughly 75% of shipments arrive late, on every carrier.
B39: =Analysis!A60 -> Chennai → Surat | E39: =Analysis!B60 -> 115 | F39: =Analysis!C60 -> 0.71304348 | G39: =Analysis!D60 -> 2.3069565
B40: =Analysis!A61 -> Gujarat → Surat | E40: =Analysis!B61 -> 124 | F40: =Analysis!C61 -> 0.7983871 | G40: =Analysis!D61 -> 2.8475806 | I40: ="Best and worst carriers differ by only "&TEXT(Analysis!C12*100,"0.0")&" percentage points in late rate, so switching carriers is not the fix." -> Best and worst carriers differ by only 5.4 percentage points in late rate, so switching carriers is not the fix.
B41: =Analysis!A62 -> Punjab → Surat | E41: =Analysis!B62 -> 111 | F41: =Analysis!C62 -> 0.78378378 | G41: =Analysis!D62 -> 2.1135135
B42: =Analysis!A63 -> Rajasthan → Surat | E42: =Analysis!B63 -> 136 | F42: =Analysis!C63 -> 0.70588235 | G42: =Analysis!D63 -> 2.2448529 | I42: ="The lever is which shipments to expedite: the smart rule expedites "&TEXT(Model!C18,"0%")&" of shipments and cuts expected cost by "&TEXT(Model!E17,"0%")&" vs never expediting, and by "&TEXT((Model!B16-Model!B17)/Model!B16,"0.0%")&" vs expediting everything." -> The lever is which shipments to expedite: the smart rule expedites 82% of shipments and cuts expected cost by 64% vs never expediting, and by 8.5% vs expediting everything.
B43: =Analysis!A64 -> Uttar Pradesh → Surat | E43: =Analysis!B64 -> 115 | F43: =Analysis!C64 -> 0.76521739 | G43: =Analysis!D64 -> 2.533913
B44: =Analysis!A65 -> Surat → Assam | E44: =Analysis!B65 -> 41 | F44: =Analysis!C65 -> 0.56097561 | G44: =Analysis!D65 -> 1.5341463 | I44: ="Lanes vary more than carriers ("&TEXT(MIN(Analysis!C60:C73),"0%")&" to "&TEXT(MAX(Analysis!C60:C73),"0%")&" late), but outbound lanes carry only "&MIN(Analysis!B65:B73)&"-"&MAX(Analysis!B65:B73)&" shipments each, so confirm on more data before acting." -> Lanes vary more than carriers (56% to 85% late), but outbound lanes carry only 37-54 shipments each, so confirm on more data before acting.
B45: =Analysis!A66 -> Surat → Gujarat | E45: =Analysis!B66 -> 42 | F45: =Analysis!C66 -> 0.76190476 | G45: =Analysis!D66 -> 2.3261905
B46: =Analysis!A67 -> Surat → Jaipur | E46: =Analysis!B67 -> 51 | F46: =Analysis!C67 -> 0.80392157 | G46: =Analysis!D67 -> 2.3156863 | I46: ="Synthetic data: read the totals as illustrative, the method as the point." -> Synthetic data: read the totals as illustrative, the method as the point.
B47: =Analysis!A68 -> Surat → Karnataka | E47: =Analysis!B68 -> 37 | F47: =Analysis!C68 -> 0.56756757 | G47: =Analysis!D68 -> 1.7891892
B48: =Analysis!A69 -> Surat → Kerala | E48: =Analysis!B69 -> 45 | F48: =Analysis!C69 -> 0.66666667 | G48: =Analysis!D69 -> 1.7844444
B49: =Analysis!A70 -> Surat → Madhya Pradesh | E49: =Analysis!B70 -> 44 | F49: =Analysis!C70 -> 0.75 | G49: =Analysis!D70 -> 2.1386364
B50: =Analysis!A71 -> Surat → Mumbai | E50: =Analysis!B71 -> 41 | F50: =Analysis!C71 -> 0.75609756 | G50: =Analysis!D71 -> 2.1609756
B51: =Analysis!A72 -> Surat → Uttarakhand | E51: =Analysis!B72 -> 54 | F51: =Analysis!C72 -> 0.85185185 | G51: =Analysis!D72 -> 3.0277778
B52: =Analysis!A73 -> Surat → West Bengal | E52: =Analysis!B73 -> 44 | F52: =Analysis!C73 -> 0.81818182 | G52: =Analysis!D73 -> 2.7795455

Sheet Analysis
A1: Where do delays come from?
A2: All figures are COUNTIFS / AVERAGEIFS / SUMIFS over the Clean sheet.
A4: 1. Carrier performance
A5: Carrier | B5: Shipments | C5: Late % | D5: Avg delay (days) | E5: Avg delay when late | F5: Avg cost per tonne | G5: % Returned or Damaged
A6: BlueDart | B6: =COUNTIFS(Clean!$AA$2:$AA$1001,$A6) -> 199 | C6: =AVERAGEIFS(Clean!$V$2:$V$1001,Clean!$AA$2:$AA$1001,$A6) -> 0.77386935 | D6: =AVERAGEIFS(Clean!$S$2:$S$1001,Clean!$AA$2:$AA$1001,$A6) -> 2.3668342 | E6: =AVERAGEIFS(Clean!$S$2:$S$1001,Clean!$AA$2:$AA$1001,$A6,Clean!$V$2:$V$1001,1) -> 3.2928571 | F6: =AVERAGEIFS(Clean!$AG$2:$AG$1001,Clean!$AA$2:$AA$1001,$A6) -> 560.0804 | G6: =(COUNTIFS(Clean!$AA$2:$AA$1001,$A6,Clean!$AC$2:$AC$1001,"Returned")+COUNTIFS(Clean!$AA$2:$AA$1001,$A6,Clean!$AC$2:$AC$1001,"Damaged"))/B6 -> 0.38693467
A7: Delhivery | B7: =COUNTIFS(Clean!$AA$2:$AA$1001,$A7) -> 193 | C7: =AVERAGEIFS(Clean!$V$2:$V$1001,Clean!$AA$2:$AA$1001,$A7) -> 0.7253886 | D7: =AVERAGEIFS(Clean!$S$2:$S$1001,Clean!$AA$2:$AA$1001,$A7) -> 2.4756477 | E7: =AVERAGEIFS(Clean!$S$2:$S$1001,Clean!$AA$2:$AA$1001,$A7,Clean!$V$2:$V$1001,1) -> 3.7107143 | F7: =AVERAGEIFS(Clean!$AG$2:$AG$1001,Clean!$AA$2:$AA$1001,$A7) -> 586.28116 | G7: =(COUNTIFS(Clean!$AA$2:$AA$1001,$A7,Clean!$AC$2:$AC$1001,"Returned")+COUNTIFS(Clean!$AA$2:$AA$1001,$A7,Clean!$AC$2:$AC$1001,"Damaged"))/B7 -> 0.40932642
A8: GATI Logistics | B8: =COUNTIFS(Clean!$AA$2:$AA$1001,$A8) -> 201 | C8: =AVERAGEIFS(Clean!$V$2:$V$1001,Clean!$AA$2:$AA$1001,$A8) -> 0.75124378 | D8: =AVERAGEIFS(Clean!$S$2:$S$1001,Clean!$AA$2:$AA$1001,$A8) -> 2.4621891 | E8: =AVERAGEIFS(Clean!$S$2:$S$1001,Clean!$AA$2:$AA$1001,$A8,Clean!$V$2:$V$1001,1) -> 3.5311258 | F8: =AVERAGEIFS(Clean!$AG$2:$AG$1001,Clean!$AA$2:$AA$1001,$A8) -> 578.76941 | G8: =(COUNTIFS(Clean!$AA$2:$AA$1001,$A8,Clean!$AC$2:$AC$1001,"Returned")+COUNTIFS(Clean!$AA$2:$AA$1001,$A8,Clean!$AC$2:$AC$1001,"Damaged"))/B8 -> 0.41791045
A9: TCI Express | B9: =COUNTIFS(Clean!$AA$2:$AA$1001,$A9) -> 214 | C9: =AVERAGEIFS(Clean!$V$2:$V$1001,Clean!$AA$2:$AA$1001,$A9) -> 0.75233645 | D9: =AVERAGEIFS(Clean!$S$2:$S$1001,Clean!$AA$2:$AA$1001,$A9) -> 2.117757 | E9: =AVERAGEIFS(Clean!$S$2:$S$1001,Clean!$AA$2:$AA$1001,$A9,Clean!$V$2:$V$1001,1) -> 3.068323 | F9: =AVERAGEIFS(Clean!$AG$2:$AG$1001,Clean!$AA$2:$AA$1001,$A9) -> 607.8529 | G9: =(COUNTIFS(Clean!$AA$2:$AA$1001,$A9,Clean!$AC$2:$AC$1001,"Returned")+COUNTIFS(Clean!$AA$2:$AA$1001,$A9,Clean!$AC$2:$AC$1001,"Damaged"))/B9 -> 0.37383178
A10: VRL Cargo | B10: =COUNTIFS(Clean!$AA$2:$AA$1001,$A10) -> 193 | C10: =AVERAGEIFS(Clean!$V$2:$V$1001,Clean!$AA$2:$AA$1001,$A10) -> 0.72020725 | D10: =AVERAGEIFS(Clean!$S$2:$S$1001,Clean!$AA$2:$AA$1001,$A10) -> 2.3134715 | E10: =AVERAGEIFS(Clean!$S$2:$S$1001,Clean!$AA$2:$AA$1001,$A10,Clean!$V$2:$V$1001,1) -> 3.5352518 | F10: =AVERAGEIFS(Clean!$AG$2:$AG$1001,Clean!$AA$2:$AA$1001,$A10) -> 586.65868 | G10: =(COUNTIFS(Clean!$AA$2:$AA$1001,$A10,Clean!$AC$2:$AC$1001,"Returned")+COUNTIFS(Clean!$AA$2:$AA$1001,$A10,Clean!$AC$2:$AC$1001,"Damaged"))/B10 -> 0.40414508
A11: All carriers | B11: =COUNTA(Clean!$AA$2:$AA$1001) -> 1000 | C11: =AVERAGE(Clean!$V$2:$V$1001) -> 0.745 | D11: =AVERAGE(Clean!$S$2:$S$1001) -> 2.3434 | E11: =AVERAGEIFS(Clean!$S$2:$S$1001,Clean!$V$2:$V$1001,1) -> 3.4163758 | F11: =AVERAGE(Clean!$AG$2:$AG$1001) -> 584.24656 | G11: =(COUNTIF(Clean!$AC$2:$AC$1001,"Returned")+COUNTIF(Clean!$AC$2:$AC$1001,"Damaged"))/B11 -> 0.398
A12: Spread (best to worst carrier) | C12: =MAX(C6:C10)-MIN(C6:C10) -> 0.053662093 | D12: =MAX(D6:D10)-MIN(D6:D10) -> 0.35789066 | E12: =MAX(E6:E10)-MIN(E6:E10) -> 0.6423913 | F12: =MAX(F6:F10)-MIN(F6:F10) -> 47.772498 | G12: =MAX(G6:G10)-MIN(G6:G10) -> 0.044078672
A14: 2. By booking month
A15: Month | B15: Shipments | C15: Late % | D15: Avg delay (days)
A16: 2025-01 | B16: =COUNTIFS(Clean!$Y$2:$Y$1001,$A16) -> 119 | C16: =AVERAGEIFS(Clean!$V$2:$V$1001,Clean!$Y$2:$Y$1001,$A16) -> 0.74789916 | D16: =AVERAGEIFS(Clean!$S$2:$S$1001,Clean!$Y$2:$Y$1001,$A16) -> 2.4260504
A17: 2025-02 | B17: =COUNTIFS(Clean!$Y$2:$Y$1001,$A17) -> 92 | C17: =AVERAGEIFS(Clean!$V$2:$V$1001,Clean!$Y$2:$Y$1001,$A17) -> 0.69565217 | D17: =AVERAGEIFS(Clean!$S$2:$S$1001,Clean!$Y$2:$Y$1001,$A17) -> 2.0923913
A18: 2025-03 | B18: =COUNTIFS(Clean!$Y$2:$Y$1001,$A18) -> 106 | C18: =AVERAGEIFS(Clean!$V$2:$V$1001,Clean!$Y$2:$Y$1001,$A18) -> 0.81132075 | D18: =AVERAGEIFS(Clean!$S$2:$S$1001,Clean!$Y$2:$Y$1001,$A18) -> 2.4764151
A19: 2025-04 | B19: =COUNTIFS(Clean!$Y$2:$Y$1001,$A19) -> 75 | C19: =AVERAGEIFS(Clean!$V$2:$V$1001,Clean!$Y$2:$Y$1001,$A19) -> 0.70666667 | D19: =AVERAGEIFS(Clean!$S$2:$S$1001,Clean!$Y$2:$Y$1001,$A19) -> 2.016
A20: 2025-05 | B20: =COUNTIFS(Clean!$Y$2:$Y$1001,$A20) -> 95 | C20: =AVERAGEIFS(Clean!$V$2:$V$1001,Clean!$Y$2:$Y$1001,$A20) -> 0.74736842 | D20: =AVERAGEIFS(Clean!$S$2:$S$1001,Clean!$Y$2:$Y$1001,$A20) -> 2.8947368
A21: 2025-06 | B21: =COUNTIFS(Clean!$Y$2:$Y$1001,$A21) -> 102 | C21: =AVERAGEIFS(Clean!$V$2:$V$1001,Clean!$Y$2:$Y$1001,$A21) -> 0.76470588 | D21: =AVERAGEIFS(Clean!$S$2:$S$1001,Clean!$Y$2:$Y$1001,$A21) -> 2.5558824
A22: 2025-07 | B22: =COUNTIFS(Clean!$Y$2:$Y$1001,$A22) -> 113 | C22: =AVERAGEIFS(Clean!$V$2:$V$1001,Clean!$Y$2:$Y$1001,$A22) -> 0.71681416 | D22: =AVERAGEIFS(Clean!$S$2:$S$1001,Clean!$Y$2:$Y$1001,$A22) -> 2.1469027
A23: 2025-08 | B23: =COUNTIFS(Clean!$Y$2:$Y$1001,$A23) -> 114 | C23: =AVERAGEIFS(Clean!$V$2:$V$1001,Clean!$Y$2:$Y$1001,$A23) -> 0.73684211 | D23: =AVERAGEIFS(Clean!$S$2:$S$1001,Clean!$Y$2:$Y$1001,$A23) -> 1.9350877
A24: 2025-09 | B24: =COUNTIFS(Clean!$Y$2:$Y$1001,$A24) -> 102 | C24: =AVERAGEIFS(Clean!$V$2:$V$1001,Clean!$Y$2:$Y$1001,$A24) -> 0.74509804 | D24: =AVERAGEIFS(Clean!$S$2:$S$1001,Clean!$Y$2:$Y$1001,$A24) -> 2.3803922
A25: 2025-10 | B25: =COUNTIFS(Clean!$Y$2:$Y$1001,$A25) -> 82 | C25: =AVERAGEIFS(Clean!$V$2:$V$1001,Clean!$Y$2:$Y$1001,$A25) -> 0.76829268 | D25: =AVERAGEIFS(Clean!$S$2:$S$1001,Clean!$Y$2:$Y$1001,$A25) -> 2.5219512
A27: 3. By material type
A28: Material | B28: Shipments | C28: Late % | D28: Avg delay (days)
A29: Finished Yarn | B29: =COUNTIFS(Clean!$I$2:$I$1001,$A29) -> 338 | C29: =AVERAGEIFS(Clean!$V$2:$V$1001,Clean!$I$2:$I$1001,$A29) -> 0.76627219 | D29: =AVERAGEIFS(Clean!$S$2:$S$1001,Clean!$I$2:$I$1001,$A29) -> 2.4837278
A30: Raw Yarn | B30: =COUNTIFS(Clean!$I$2:$I$1001,$A30) -> 357 | C30: =AVERAGEIFS(Clean!$V$2:$V$1001,Clean!$I$2:$I$1001,$A30) -> 0.7535014 | D30: =AVERAGEIFS(Clean!$S$2:$S$1001,Clean!$I$2:$I$1001,$A30) -> 2.2207283
A31: Semi-Processed Yarn | B31: =COUNTIFS(Clean!$I$2:$I$1001,$A31) -> 305 | C31: =AVERAGEIFS(Clean!$V$2:$V$1001,Clean!$I$2:$I$1001,$A31) -> 0.71147541 | D31: =AVERAGEIFS(Clean!$S$2:$S$1001,Clean!$I$2:$I$1001,$A31) -> 2.3314754
A33: 4. By shipment type
A34: Type | B34: Shipments | C34: Late % | D34: Avg delay (days)
A35: Inbound | B35: =COUNTIFS(Clean!$B$2:$B$1001,$A35) -> 601 | C35: =AVERAGEIFS(Clean!$V$2:$V$1001,Clean!$B$2:$B$1001,$A35) -> 0.75207987 | D35: =AVERAGEIFS(Clean!$S$2:$S$1001,Clean!$B$2:$B$1001,$A35) -> 2.4121464
A36: Outbound | B36: =COUNTIFS(Clean!$B$2:$B$1001,$A36) -> 399 | C36: =AVERAGEIFS(Clean!$V$2:$V$1001,Clean!$B$2:$B$1001,$A36) -> 0.73433584 | D36: =AVERAGEIFS(Clean!$S$2:$S$1001,Clean!$B$2:$B$1001,$A36) -> 2.2398496
A38: 5. By temperature sensitivity
A39: Temperature sensitive | B39: Shipments | C39: Late % | D39: Avg delay (days)
A40: Yes | B40: =COUNTIFS(Clean!$AB$2:$AB$1001,$A40) -> 482 | C40: =AVERAGEIFS(Clean!$V$2:$V$1001,Clean!$AB$2:$AB$1001,$A40) -> 0.78215768 | D40: =AVERAGEIFS(Clean!$S$2:$S$1001,Clean!$AB$2:$AB$1001,$A40) -> 2.4979253
A41: No | B41: =COUNTIFS(Clean!$AB$2:$AB$1001,$A41) -> 518 | C41: =AVERAGEIFS(Clean!$V$2:$V$1001,Clean!$AB$2:$AB$1001,$A41) -> 0.71042471 | D41: =AVERAGEIFS(Clean!$S$2:$S$1001,Clean!$AB$2:$AB$1001,$A41) -> 2.1996139
A43: 6. Inbound shipments by origin region
A44: Origin region | B44: Shipments | C44: Late % | D44: Avg delay (days)
A45: North | B45: =COUNTIFS(Clean!$F$2:$F$1001,$A45,Clean!$B$2:$B$1001,"Inbound") -> 362 | C45: =AVERAGEIFS(Clean!$V$2:$V$1001,Clean!$F$2:$F$1001,$A45,Clean!$B$2:$B$1001,"Inbound") -> 0.74861878 | D45: =AVERAGEIFS(Clean!$S$2:$S$1001,Clean!$F$2:$F$1001,$A45,Clean!$B$2:$B$1001,"Inbound") -> 2.2964088
A46: South | B46: =COUNTIFS(Clean!$F$2:$F$1001,$A46,Clean!$B$2:$B$1001,"Inbound") -> 115 | C46: =AVERAGEIFS(Clean!$V$2:$V$1001,Clean!$F$2:$F$1001,$A46,Clean!$B$2:$B$1001,"Inbound") -> 0.71304348 | D46: =AVERAGEIFS(Clean!$S$2:$S$1001,Clean!$F$2:$F$1001,$A46,Clean!$B$2:$B$1001,"Inbound") -> 2.3069565
...

Sheet Model
A1: Which shipments are worth expediting?
A2: Expedite a shipment only when the surcharge is less than the stockout loss it is expected to prevent. Change the yellow inputs and everything recalculates.
A3: Inputs
A4: Stockout cost multiplier | B4: 1 | C4: 1.0 = stockout costs as recorded in the data
A5: Expedite effectiveness (share of delay risk removed) | B5: 1 | C5: 100% = an expedited shipment never runs late
A7: Assumptions
A8: 1. Base shipping cost is paid either way, so only the expedite surcharge is extra.
A9: 2. Chance of delay = that carrier's historical late rate (in-sample, so illustrative).
A10: 3. Expected stockout cost = chance of delay × quantity × stockout cost per tonne.
A11: 4. Data is synthetic (1,000 shipments, Jan–Oct 2025), so treat totals as illustrative.
A13: Policy comparison
A14: Policy | B14: Total expected cost | C14: Shipments expedited | D14: Saving vs never | E14: Saving %
A15: Never expedite | B15: =SUM(Model_Detail!$J$2:$J$1001) -> 7572796.1 | C15: 0 | D15: =$B$15-B15 -> 0 | E15: =IF($B$15=0,0,D15/$B$15) -> 0
A16: Always expedite | B16: =SUM(Model_Detail!$K$2:$K$1001) -> 2989634.1 | C16: =COUNTA(Model_Detail!$A$2:$A$1001) -> 1000 | D16: =$B$15-B16 -> 4583162 | E16: =IF($B$15=0,0,D16/$B$15) -> 0.60521397
A17: Smart rule | B17: =SUM(Model_Detail!$L$2:$L$1001) -> 2735054.6 | C17: =COUNTIF(Model_Detail!$I$2:$I$1001,"Expedite") -> 822 | D17: =$B$15-B17 -> 4837741.5 | E17: =IF($B$15=0,0,D17/$B$15) -> 0.63883161
A18: Share of shipments the smart rule expedites | C18: =C17/C16 -> 0.822
A20: Sensitivity: saving vs never expedite (₹) | G20: Sensitivity: % of shipments expedited
A21: Rows: stockout cost multiplier. Columns: expedite effectiveness.
A22: Multiplier \ Effectiveness | B22: 0.5 | C22: 0.75 | D22: 1 | G22: Multiplier \ Effectiveness | H22: 0.5 | I22: 0.75 | J22: 1
A23: 0.25 | B23: =SUMPRODUCT(--(Model_Detail!$E$2:$E$1001<B$22*$A23*Model_Detail!$G$2:$G$1001),B$22*$A23*Model_Detail!$G$2:$G$1001-Model_Detail!$E$2:$E$1001) -> 18910.088 | C23: =SUMPRODUCT(--(Model_Detail!$E$2:$E$1001<C$22*$A23*Model_Detail!$G$2:$G$1001),C$22*$A23*Model_Detail!$G$2:$G$1001-Model_Detail!$E$2:$E$1001) -> 98092.787 | D23: =SUMPRODUCT(--(Model_Detail!$E$2:$E$1001<D$22*$A23*Model_Detail!$G$2:$G$1001),D$22*$A23*Model_Detail!$G$2:$G$1001-Model_Detail!$E$2:$E$1001) -> 256187.56 | G23: 0.25 | H23: =SUMPRODUCT(--(Model_Detail!$E$2:$E$1001<H$22*$G23*Model_Detail!$G$2:$G$1001))/COUNTA(Model_Detail!$A$2:$A$1001) -> 0.045 | I23: =SUMPRODUCT(--(Model_Detail!$E$2:$E$1001<I$22*$G23*Model_Detail!$G$2:$G$1001))/COUNTA(Model_Detail!$A$2:$A$1001) -> 0.145 | J23: =SUMPRODUCT(--(Model_Detail!$E$2:$E$1001<J$22*$G23*Model_Detail!$G$2:$G$1001))/COUNTA(Model_Detail!$A$2:$A$1001) -> 0.241
A24: 0.5 | B24: =SUMPRODUCT(--(Model_Detail!$E$2:$E$1001<B$22*$A24*Model_Detail!$G$2:$G$1001),B$22*$A24*Model_Detail!$G$2:$G$1001-Model_Detail!$E$2:$E$1001) -> 256187.56 | C24: =SUMPRODUCT(--(Model_Detail!$E$2:$E$1001<C$22*$A24*Model_Detail!$G$2:$G$1001),C$22*$A24*Model_Detail!$G$2:$G$1001-Model_Detail!$E$2:$E$1001) -> 756830.07 | D24: =SUMPRODUCT(--(Model_Detail!$E$2:$E$1001<D$22*$A24*Model_Detail!$G$2:$G$1001),D$22*$A24*Model_Detail!$G$2:$G$1001-Model_Detail!$E$2:$E$1001) -> 1446921.8 | G24: 0.5 | H24: =SUMPRODUCT(--(Model_Detail!$E$2:$E$1001<H$22*$G24*Model_Detail!$G$2:$G$1001))/COUNTA(Model_Detail!$A$2:$A$1001) -> 0.241 | I24: =SUMPRODUCT(--(Model_Detail!$E$2:$E$1001<I$22*$G24*Model_Detail!$G$2:$G$1001))/COUNTA(Model_Detail!$A$2:$A$1001) -> 0.434 | J24: =SUMPRODUCT(--(Model_Detail!$E$2:$E$1001<J$22*$G24*Model_Detail!$G$2:$G$1001))/COUNTA(Model_Detail!$A$2:$A$1001) -> 0.593
A25: 0.75 | B25: =SUMPRODUCT(--(Model_Detail!$E$2:$E$1001<B$22*$A25*Model_Detail!$G$2:$G$1001),B$22*$A25*Model_Detail!$G$2:$G$1001-Model_Detail!$E$2:$E$1001) -> 756830.07 | C25: =SUMPRODUCT(--(Model_Detail!$E$2:$E$1001<C$22*$A25*Model_Detail!$G$2:$G$1001),C$22*$A25*Model_Detail!$G$2:$G$1001-Model_Detail!$E$2:$E$1001) -> 1831119.1 | D25: =SUMPRODUCT(--(Model_Detail!$E$2:$E$1001<D$22*$A25*Model_Detail!$G$2:$G$1001),D$22*$A25*Model_Detail!$G$2:$G$1001-Model_Detail!$E$2:$E$1001) -> 3071494.1 | G25: 0.75 | H25: =SUMPRODUCT(--(Model_Detail!$E$2:$E$1001<H$22*$G25*Model_Detail!$G$2:$G$1001))/COUNTA(Model_Detail!$A$2:$A$1001) -> 0.434 | I25: =SUMPRODUCT(--(Model_Detail!$E$2:$E$1001<I$22*$G25*Model_Detail!$G$2:$G$1001))/COUNTA(Model_Detail!$A$2:$A$1001) -> 0.63 | J25: =SUMPRODUCT(--(Model_Detail!$E$2:$E$1001<J$22*$G25*Model_Detail!$G$2:$G$1001))/COUNTA(Model_Detail!$A$2:$A$1001) -> 0.742
A26: 1 | B26: =SUMPRODUCT(--(Model_Detail!$E$2:$E$1001<B$22*$A26*Model_Detail!$G$2:$G$1001),B$22*$A26*Model_Detail!$G$2:$G$1001-Model_Detail!$E$2:$E$1001) -> 1446921.8 | C26: =SUMPRODUCT(--(Model_Detail!$E$2:$E$1001<C$22*$A26*Model_Detail!$G$2:$G$1001),C$22*$A26*Model_Detail!$G$2:$G$1001-Model_Detail!$E$2:$E$1001) -> 3071494.1 | D26: =SUMPRODUCT(--(Model_Detail!$E$2:$E$1001<D$22*$A26*Model_Detail!$G$2:$G$1001),D$22*$A26*Model_Detail!$G$2:$G$1001-Model_Detail!$E$2:$E$1001) -> 4837741.5 | G26: 1 | H26: =SUMPRODUCT(--(Model_Detail!$E$2:$E$1001<H$22*$G26*Model_Detail!$G$2:$G$1001))/COUNTA(Model_Detail!$A$2:$A$1001) -> 0.593 | I26: =SUMPRODUCT(--(Model_Detail!$E$2:$E$1001<I$22*$G26*Model_Detail!$G$2:$G$1001))/COUNTA(Model_Detail!$A$2:$A$1001) -> 0.742 | J26: =SUMPRODUCT(--(Model_Detail!$E$2:$E$1001<J$22*$G26*Model_Detail!$G$2:$G$1001))/COUNTA(Model_Detail!$A$2:$A$1001) -> 0.822
A27: 1.25 | B27: =SUMPRODUCT(--(Model_Detail!$E$2:$E$1001<B$22*$A27*Model_Detail!$G$2:$G$1001),B$22*$A27*Model_Detail!$G$2:$G$1001-Model_Detail!$E$2:$E$1001) -> 2230159.4 | C27: =SUMPRODUCT(--(Model_Detail!$E$2:$E$1001<C$22*$A27*Model_Detail!$G$2:$G$1001),C$22*$A27*Model_Detail!$G$2:$G$1001-Model_Detail!$E$2:$E$1001) -> 4389041.3 | D27: =SUMPRODUCT(--(Model_Detail!$E$2:$E$1001<D$22*$A27*Model_Detail!$G$2:$G$1001),D$22*$A27*Model_Detail!$G$2:$G$1001-Model_Detail!$E$2:$E$1001) -> 6662095.5 | G27: 1.25 | H27: =SUMPRODUCT(--(Model_Detail!$E$2:$E$1001<H$22*$G27*Model_Detail!$G$2:$G$1001))/COUNTA(Model_Detail!$A$2:$A$1001) -> 0.673 | I27: =SUMPRODUCT(--(Model_Detail!$E$2:$E$1001<I$22*$G27*Model_Detail!$G$2:$G$1001))/COUNTA(Model_Detail!$A$2:$A$1001) -> 0.805 | J27: =SUMPRODUCT(--(Model_Detail!$E$2:$E$1001<J$22*$G27*Model_Detail!$G$2:$G$1001))/COUNTA(Model_Detail!$A$2:$A$1001) -> 0.865
A28: 1.5 | B28: =SUMPRODUCT(--(Model_Detail!$E$2:$E$1001<B$22*$A28*Model_Detail!$G$2:$G$1001),B$22*$A28*Model_Detail!$G$2:$G$1001-Model_Detail!$E$2:$E$1001) -> 3071494.1 | C28: =SUMPRODUCT(--(Model_Detail!$E$2:$E$1001<C$22*$A28*Model_Detail!$G$2:$G$1001),C$22*$A28*Model_Detail!$G$2:$G$1001-Model_Detail!$E$2:$E$1001) -> 5745374.4 | D28: =SUMPRODUCT(--(Model_Detail!$E$2:$E$1001<D$22*$A28*Model_Detail!$G$2:$G$1001),D$22*$A28*Model_Detail!$G$2:$G$1001-Model_Detail!$E$2:$E$1001) -> 8512148.6 | G28: 1.5 | H28: =SUMPRODUCT(--(Model_Detail!$E$2:$E$1001<H$22*$G28*Model_Detail!$G$2:$G$1001))/COUNTA(Model_Detail!$A$2:$A$1001) -> 0.742 | I28: =SUMPRODUCT(--(Model_Detail!$E$2:$E$1001<I$22*$G28*Model_Detail!$G$2:$G$1001))/COUNTA(Model_Detail!$A$2:$A$1001) -> 0.854 | J28: =SUMPRODUCT(--(Model_Detail!$E$2:$E$1001<J$22*$G28*Model_Detail!$G$2:$G$1001))/COUNTA(Model_Detail!$A$2:$A$1001) -> 0.898
A29: 2 | B29: =SUMPRODUCT(--(Model_Detail!$E$2:$E$1001<B$22*$A29*Model_Detail!$G$2:$G$1001),B$22*$A29*Model_Detail!$G$2:$G$1001-Model_Detail!$E$2:$E$1001) -> 4837741.5 | C29: =SUMPRODUCT(--(Model_Detail!$E$2:$E$1001<C$22*$A29*Model_Detail!$G$2:$G$1001),C$22*$A29*Model_Detail!$G$2:$G$1001-Model_Detail!$E$2:$E$1001) -> 8512148.6 | D29: =SUMPRODUCT(--(Model_Detail!$E$2:$E$1001<D$22*$A29*Model_Detail!$G$2:$G$1001),D$22*$A29*Model_Detail!$G$2:$G$1001-Model_Detail!$E$2:$E$1001) -> 12244261 | G29: 2 | H29: =SUMPRODUCT(--(Model_Detail!$E$2:$E$1001<H$22*$G29*Model_Detail!$G$2:$G$1001))/COUNTA(Model_Detail!$A$2:$A$1001) -> 0.822 | I29: =SUMPRODUCT(--(Model_Detail!$E$2:$E$1001<I$22*$G29*Model_Detail!$G$2:$G$1001))/COUNTA(Model_Detail!$A$2:$A$1001) -> 0.898 | J29: =SUMPRODUCT(--(Model_Detail!$E$2:$E$1001<J$22*$G29*Model_Detail!$G$2:$G$1001))/COUNTA(Model_Detail!$A$2:$A$1001) -> 0.933
A31: Single-shipment calculator
A32: Pick a shipment. To find its break-even with Goal Seek: Data → What-If Analysis → Goal Seek, set the Net benefit cell to 0 by changing the yellow stockout cell. The answer should match the break-even formula.
A33: Shipment ID (pick from list) | B33: SHP0001
A34: Carrier | B34: =IFERROR(INDEX(Model_Detail!$B$2:$B$1001,MATCH($B$33,Model_Detail!$A$2:$A$1001,0)),"not found") -> BlueDart
A35: Quantity (tonnes) | B35: =IFERROR(INDEX(Model_Detail!$C$2:$C$1001,MATCH($B$33,Model_Detail!$A$2:$A$1001,0)),0) -> 8.12
A36: Expedite surcharge | B36: =IFERROR(INDEX(Model_Detail!$E$2:$E$1001,MATCH($B$33,Model_Detail!$A$2:$A$1001,0)),0) -> 3404.46
A37: Chance of delay (carrier late rate) | B37: =IFERROR(INDEX(Model_Detail!$F$2:$F$1001,MATCH($B$33,Model_Detail!$A$2:$A$1001,0)),0) -> 0.77386935
A38: Recorded stockout cost per tonne | B38: =IFERROR(INDEX(Model_Detail!$D$2:$D$1001,MATCH($B$33,Model_Detail!$A$2:$A$1001,0)),0) -> 1208.07
A39: Stockout cost per tonne to test (input) | B39: 1208.07
A40: Expected stockout cost | B40: =B37*B35*B39*$B$4 -> 7591.2933
A41: Delay risk removed by expediting | B41: =$B$5*B40 -> 7591.2933
A42: Net benefit of expediting | B42: =B41-B36 -> 4186.8333
A43: Decision | B43: =IF(B42>0,"Expedite","Standard") -> Expedite
A44: Break-even stockout cost per tonne (formula) | B44: =IFERROR(B36/(B37*B35*$B$5*$B$4),"") -> 541.78199

Sheet Model_Detail
A1: shipment_id | B1: carrier | C1: quantity_tonnes | D1: stockout_cost_per_tonne | E1: expedite_surcharge | F1: p_late (carrier history) | G1: base_risk (p × qty × stockout) | H1: expected_stockout_cost | I1: decision | J1: cost_if_never_expedite | K1: cost_if_always_expedite | L1: cost_under_rule | M1: saving_vs_never | N1: breakeven_stockout_per_tonne
A2: =Clean!A2 -> SHP0001 | B2: =Clean!AA2 -> BlueDart | C2: =Clean!J2 -> 8.12 | D2: =Clean!AF2 -> 1208.07 | E2: =Clean!AE2 -> 3404.46 | F2: =AVERAGEIFS(Clean!$V$2:$V$1001,Clean!$AA$2:$AA$1001,B2) -> 0.77386935 | G2: =F2*C2*D2 -> 7591.2933 | H2: =G2*Model!$B$4 -> 7591.2933 | I2: =IF(E2<Model!$B$5*H2,"Expedite","Standard") -> Expedite | J2: =H2 -> 7591.2933 | K2: =E2+(1-Model!$B$5)*H2 -> 3404.46 | L2: =IF(I2="Expedite",K2,J2) -> 3404.46 | M2: =J2-L2 -> 4186.8333 | N2: =IFERROR(E2/(F2*C2*Model!$B$5),"") -> 541.78199
A3: =Clean!A3 -> SHP0002 | B3: =Clean!AA3 -> Delhivery | C3: =Clean!J3 -> 1.39 | D3: =Clean!AF3 -> 931.95 | E3: =Clean!AE3 -> 3099.03 | F3: =AVERAGEIFS(Clean!$V$2:$V$1001,Clean!$AA$2:$AA$1001,B3) -> 0.7253886 | G3: =F3*C3*D3 -> 939.67601 | H3: =G3*Model!$B$4 -> 939.67601 | I3: =IF(E3<Model!$B$5*H3,"Expedite","Standard") -> Standard | J3: =H3 -> 939.67601 | K3: =E3+(1-Model!$B$5)*H3 -> 3099.03 | L3: =IF(I3="Expedite",K3,J3) -> 939.67601 | M3: =J3-L3 -> 0 | N3: =IFERROR(E3/(F3*C3*Model!$B$5),"") -> 3073.5498
A4: =Clean!A4 -> SHP0003 | B4: =Clean!AA4 -> VRL Cargo | C4: =Clean!J4 -> 6.53 | D4: =Clean!AF4 -> 1107.54 | E4: =Clean!AE4 -> 1185.8 | F4: =AVERAGEIFS(Clean!$V$2:$V$1001,Clean!$AA$2:$AA$1001,B4) -> 0.72020725 | G4: =F4*C4*D4 -> 5208.709 | H4: =G4*Model!$B$4 -> 5208.709 | I4: =IF(E4<Model!$B$5*H4,"Expedite","Standard") -> Expedite | J4: =H4 -> 5208.709 | K4: =E4+(1-Model!$B$5)*H4 -> 1185.8 | L4: =IF(I4="Expedite",K4,J4) -> 1185.8 | M4: =J4-L4 -> 4022.909 | N4: =IFERROR(E4/(F4*C4*Model!$B$5),"") -> 252.13943
A5: =Clean!A5 -> SHP0004 | B5: =Clean!AA5 -> Delhivery | C5: =Clean!J5 -> 4.24 | D5: =Clean!AF5 -> 1184.23 | E5: =Clean!AE5 -> 1390.69 | F5: =AVERAGEIFS(Clean!$V$2:$V$1001,Clean!$AA$2:$AA$1001,B5) -> 0.7253886 | G5: =F5*C5*D5 -> 3642.2742 | H5: =G5*Model!$B$4 -> 3642.2742 | I5: =IF(E5<Model!$B$5*H5,"Expedite","Standard") -> Expedite | J5: =H5 -> 3642.2742 | K5: =E5+(1-Model!$B$5)*H5 -> 1390.69 | L5: =IF(I5="Expedite",K5,J5) -> 1390.69 | M5: =J5-L5 -> 2251.5842 | N5: =IFERROR(E5/(F5*C5*Model!$B$5),"") -> 452.16167
A6: =Clean!A6 -> SHP0005 | B6: =Clean!AA6 -> VRL Cargo | C6: =Clean!J6 -> 9.36 | D6: =Clean!AF6 -> 1067.7 | E6: =Clean!AE6 -> 1831.77 | F6: =AVERAGEIFS(Clean!$V$2:$V$1001,Clean!$AA$2:$AA$1001,B6) -> 0.72020725 | G6: =F6*C6*D6 -> 7197.5151 | H6: =G6*Model!$B$4 -> 7197.5151 | I6: =IF(E6<Model!$B$5*H6,"Expedite","Standard") -> Expedite | J6: =H6 -> 7197.5151 | K6: =E6+(1-Model!$B$5)*H6 -> 1831.77 | L6: =IF(I6="Expedite",K6,J6) -> 1831.77 | M6: =J6-L6 -> 5365.7451 | N6: =IFERROR(E6/(F6*C6*Model!$B$5),"") -> 271.73001
A7: =Clean!A7 -> SHP0006 | B7: =Clean!AA7 -> GATI Logistics | C7: =Clean!J7 -> 1.59 | D7: =Clean!AF7 -> 1070.44 | E7: =Clean!AE7 -> 2306.16 | F7: =AVERAGEIFS(Clean!$V$2:$V$1001,Clean!$AA$2:$AA$1001,B7) -> 0.75124378 | G7: =F7*C7*D7 -> 1278.6166 | H7: =G7*Model!$B$4 -> 1278.6166 | I7: =IF(E7<Model!$B$5*H7,"Expedite","Standard") -> Standard | J7: =H7 -> 1278.6166 | K7: =E7+(1-Model!$B$5)*H7 -> 2306.16 | L7: =IF(I7="Expedite",K7,J7) -> 1278.6166 | M7: =J7-L7 -> 0 | N7: =IFERROR(E7/(F7*C7*Model!$B$5),"") -> 1930.685
A8: =Clean!A8 -> SHP0007 | B8: =Clean!AA8 -> BlueDart | C8: =Clean!J8 -> 10.9 | D8: =Clean!AF8 -> 796.27 | E8: =Clean!AE8 -> 2104 | F8: =AVERAGEIFS(Clean!$V$2:$V$1001,Clean!$AA$2:$AA$1001,B8) -> 0.77386935 | G8: =F8*C8*D8 -> 6716.6775 | H8: =G8*Model!$B$4 -> 6716.6775 | I8: =IF(E8<Model!$B$5*H8,"Expedite","Standard") -> Expedite | J8: =H8 -> 6716.6775 | K8: =E8+(1-Model!$B$5)*H8 -> 2104 | L8: =IF(I8="Expedite",K8,J8) -> 2104 | M8: =J8-L8 -> 4612.6775 | N8: =IFERROR(E8/(F8*C8*Model!$B$5),"") -> 249.43167
A9: =Clean!A9 -> SHP0008 | B9: =Clean!AA9 -> Delhivery | C9: =Clean!J9 -> 4.14 | D9: =Clean!AF9 -> 1211.34 | E9: =Clean!AE9 -> 1795.37 | F9: =AVERAGEIFS(Clean!$V$2:$V$1001,Clean!$AA$2:$AA$1001,B9) -> 0.7253886 | G9: =F9*C9*D9 -> 3637.7858 | H9: =G9*Model!$B$4 -> 3637.7858 | I9: =IF(E9<Model!$B$5*H9,"Expedite","Standard") -> Expedite | J9: =H9 -> 3637.7858 | K9: =E9+(1-Model!$B$5)*H9 -> 1795.37 | L9: =IF(I9="Expedite",K9,J9) -> 1795.37 | M9: =J9-L9 -> 1842.4158 | N9: =IFERROR(E9/(F9*C9*Model!$B$5),"") -> 597.83715
A10: =Clean!A10 -> SHP0009 | B10: =Clean!AA10 -> VRL Cargo | C10: =Clean!J10 -> 16.01 | D10: =Clean!AF10 -> 1137.56 | E10: =Clean!AE10 -> 3918.42 | F10: =AVERAGEIFS(Clean!$V$2:$V$1001,Clean!$AA$2:$AA$1001,B10) -> 0.72020725 | G10: =F10*C10*D10 -> 13116.656 | H10: =G10*Model!$B$4 -> 13116.656 | I10: =IF(E10<Model!$B$5*H10,"Expedite","Standard") -> Expedite | J10: =H10 -> 13116.656 | K10: =E10+(1-Model!$B$5)*H10 -> 3918.42 | L10: =IF(I10="Expedite",K10,J10) -> 3918.42 | M10: =J10-L10 -> 9198.2362 | N10: =IFERROR(E10/(F10*C10*Model!$B$5),"") -> 339.83035
A11: =Clean!A11 -> SHP0010 | B11: =Clean!AA11 -> VRL Cargo | C11: =Clean!J11 -> 17.86 | D11: =Clean!AF11 -> 540.43 | E11: =Clean!AE11 -> 2024.27 | F11: =AVERAGEIFS(Clean!$V$2:$V$1001,Clean!$AA$2:$AA$1001,B11) -> 0.72020725 | G11: =F11*C11*D11 -> 6951.4979 | H11: =G11*Model!$B$4 -> 6951.4979 | I11: =IF(E11<Model!$B$5*H11,"Expedite","Standard") -> Expedite | J11: =H11 -> 6951.4979 | K11: =E11+(1-Model!$B$5)*H11 -> 2024.27 | L11: =IF(I11="Expedite",K11,J11) -> 2024.27 | M11: =J11-L11 -> 4927.2279 | N11: =IFERROR(E11/(F11*C11*Model!$B$5),"") -> 157.37274
A12: =Clean!A12 -> SHP0011 | B12: =Clean!AA12 -> BlueDart | C12: =Clean!J12 -> 14.5 | D12: =Clean!AF12 -> 1104.42 | E12: =Clean!AE12 -> 1557.33 | F12: =AVERAGEIFS(Clean!$V$2:$V$1001,Clean!$AA$2:$AA$1001,B12) -> 0.77386935 | G12: =F12*C12*D12 -> 12392.813 | H12: =G12*Model!$B$4 -> 12392.813 | I12: =IF(E12<Model!$B$5*H12,"Expedite","Standard") -> Expedite | J12: =H12 -> 12392.813 | K12: =E12+(1-Model!$B$5)*H12 -> 1557.33 | L12: =IF(I12="Expedite",K12,J12) -> 1557.33 | M12: =J12-L12 -> 10835.483 | N12: =IFERROR(E12/(F12*C12*Model!$B$5),"") -> 138.78579
A13: =Clean!A13 -> SHP0012 | B13: =Clean!AA13 -> VRL Cargo | C13: =Clean!J13 -> 11.26 | D13: =Clean!AF13 -> 1133.4 | E13: =Clean!AE13 -> 4232.48 | F13: =AVERAGEIFS(Clean!$V$2:$V$1001,Clean!$AA$2:$AA$1001,B13) -> 0.72020725 | G13: =F13*C13*D13 -> 9191.3455 | H13: =G13*Model!$B$4 -> 9191.3455 | I13: =IF(E13<Model!$B$5*H13,"Expedite","Standard") -> Expedite | J13: =H13 -> 9191.3455 | K13: =E13+(1-Model!$B$5)*H13 -> 4232.48 | L13: =IF(I13="Expedite",K13,J13) -> 4232.48 | M13: =J13-L13 -> 4958.8655 | N13: =IFERROR(E13/(F13*C13*Model!$B$5),"") -> 521.9141
... A1001: =Clean!A1001 -> SHP1000 | B1001: =Clean!AA1001 -> TCI Express | C1001: =Clean!J1001 -> 14.07 | D1001: =Clean!AF1001 -> 887.07 | E1001: =Clean!AE1001 -> 4671.39 | F1001: =AVERAGEIFS(Clean!$V$2:$V$1001,Clean!$AA$2:$AA$1001,B1001) -> 0.75233645 | G1001: =F1001*C1001*D1001 -> 9389.9676 | H1001: =G1001*Model!$B$4 -> 9389.9676 | I1001: =IF(E1001<Model!$B$5*H1001,"Expedite","Standard") -> Expedite | J1001: =H1001 -> 9389.9676 | K1001: =E1001+(1-Model!$B$5)*H1001 -> 4671.39 | L1001: =IF(I1001="Expedite",K1001,J1001) -> 4671.39 | M1001: =J1001-L1001 -> 4718.5776 | N1001: =IFERROR(E1001/(F1001*C1001*Model!$B$5),"") -> 441.3061

Sheet Data_Quality
A1: Data quality checks
A2: Every result is a formula over Raw or Clean. Status turns red if a check fails.
A4: Check | B4: Result | C4: Expected | D4: Status | E4: How it is checked
A5: Rows loaded | B5: =COUNTA(Raw!$A$2:$A$1001) -> 1000 | C5: 1000 | D5: =IF(B5=C5,"PASS","CHECK") -> PASS | E5: COUNTA of shipment_id
A6: Blank cells in Raw | B6: =COUNTBLANK(Raw!$A$2:$S$1001) -> 0 | C6: 0 | D6: =IF(B6=C6,"PASS","CHECK") -> PASS | E6: COUNTBLANK over all 19 columns
A7: Duplicate shipment IDs | B7: =SUMPRODUCT(--(COUNTIF(Raw!$A$2:$A$1001,Raw!$A$2:$A$1001)>1)) -> 0 | C7: 0 | D7: =IF(B7=C7,"PASS","CHECK") -> PASS | E7: COUNTIF of each ID against the whole column
A8: Locations not in Location_Map | B8: =COUNTIF(Clean!$E$2:$H$1001,"UNMAPPED") -> 0 | C8: 0 | D8: =IF(B8=C8,"PASS","CHECK") -> PASS | E8: lookup fallback value in Clean E:H
A9: delay_days differs from arrival − scheduled arrival | B9: =COUNTIF(Clean!$U$2:$U$1001,"MISMATCH") -> 0 | C9: 0 | D9: =IF(B9=C9,"PASS","CHECK") -> PASS | E9: recomputed in Clean column T
A10: delay_flag disagrees with delay_days | B10: =COUNTIF(Clean!$W$2:$W$1001,"MISMATCH") -> 0 | C10: 0 | D10: =IF(B10=C10,"PASS","CHECK") -> PASS | E10: flag should be 1 exactly when delay > 0
A11: Arrived before it departed | B11: =SUMPRODUCT(--(Clean!$O$2:$O$1001<Clean!$N$2:$N$1001)) -> 0 | C11: 0 | D11: =IF(B11=C11,"PASS","CHECK") -> PASS | E11: timestamp order
A12: Scheduled to depart before it was booked | B12: =SUMPRODUCT(--(Clean!$L$2:$L$1001<Clean!$K$2:$K$1001)) -> 0 | C12: 0 | D12: =IF(B12=C12,"PASS","CHECK") -> PASS | E12: date order
A13: Shipments that arrived early (negative delay) | B13: =COUNTIF(Clean!$S$2:$S$1001,"<0") -> 244 | C13: info | D13: INFO | E13: valid early arrivals, not errors; kept in the data

Sheet Clean
A1: shipment_id | B1: shipment_type | C1: source | D1: destination | E1: source_state | F1: source_region | G1: dest_state | H1: dest_region | I1: material_type | J1: quantity_tonnes | K1: booking_date | L1: scheduled_departure | M1: scheduled_arrival | N1: actual_departure | O1: actual_arrival | P1: lead_time_days | Q1: planned_transit_days | R1: actual_transit_days | S1: delay_days | T1: delay_recomputed | U1: delay_check | V1: delay_flag | W1: flag_check | X1: delay_category | Y1: booking_month | Z1: route | AA1: carrier | AB1: temperature_sensitive | AC1: remarks | AD1: shipping_cost | AE1: expedite_surcharge | AF1: stockout_cost_per_tonne | AG1: cost_per_tonne
A2: =Raw!A2 -> SHP0001 | B2: =Raw!B2 -> Outbound | C2: =Raw!C2 -> Surat | D2: =Raw!D2 -> Mumbai | E2: =IFERROR(INDEX(Location_Map!$B$2:$B$15,MATCH(C2,Location_Map!$A$2:$A$15,0)),"UNMAPPED") -> Gujarat | F2: =IFERROR(INDEX(Location_Map!$C$2:$C$15,MATCH(C2,Location_Map!$A$2:$A$15,0)),"UNMAPPED") -> West | G2: =IFERROR(INDEX(Location_Map!$B$2:$B$15,MATCH(D2,Location_Map!$A$2:$A$15,0)),"UNMAPPED") -> Maharashtra | H2: =IFERROR(INDEX(Location_Map!$C$2:$C$15,MATCH(D2,Location_Map!$A$2:$A$15,0)),"UNMAPPED") -> West | I2: =Raw!E2 -> Finished Yarn | J2: =Raw!F2 -> 8.12 | K2: =DATE(LEFT(Raw!G2,4),MID(Raw!G2,6,2),MID(Raw!G2,9,2)) -> 45943 | L2: =DATE(LEFT(Raw!H2,4),MID(Raw!H2,6,2),MID(Raw!H2,9,2)) -> 45946 | M2: =DATE(LEFT(Raw!I2,4),MID(Raw!I2,6,2),MID(Raw!I2,9,2)) -> 45952 | N2: =DATE(LEFT(Raw!J2,4),MID(Raw!J2,6,2),MID(Raw!J2,9,2))+TIME(MID(Raw!J2,12,2),MID(Raw!J2,15,2),MID(Raw!J2,18,2)) -> 45946.042 | O2: =DATE(LEFT(Raw!K2,4),MID(Raw!K2,6,2),MID(Raw!K2,9,2))+TIME(MID(Raw!K2,12,2),MID(Raw!K2,15,2),MID(Raw!K2,18,2)) -> 45951 | P2: =L2-K2 -> 3 | Q2: =M2-L2 -> 6 | R2: =O2-N2 -> 4.9583333 | S2: =Raw!L2 -> -1 | T2: =O2-M2 -> -1 | U2: =IF(ABS(T2-S2)<0.01,"OK","MISMATCH") -> OK | V2: =Raw!M2 -> 0 | W2: =IF((S2>0)=(V2=1),"OK","MISMATCH") -> OK | X2: =_xlfn.IFS(S2<=0,"Early/On time",S2<=2,"Minor (up to 2 days)",S2<=5,"Moderate (2-5 days)",TRUE(),"Severe (over 5 days)") -> Early/On time | Y2: =YEAR(K2)&"-"&TEXT(MONTH(K2),"00") -> 2025-10 | Z2: =C2&" → "&D2 -> Surat → Mumbai | AA2: =Raw!Q2 -> BlueDart | AB2: =Raw!R2 -> Yes | AC2: =Raw!S2 -> Expedited | AD2: =Raw!N2 -> 3889.18 | AE2: =Raw!O2 -> 3404.46 | AF2: =Raw!P2 -> 1208.07 | AG2: =AD2/J2 -> 478.96305
A3: =Raw!A3 -> SHP0002 | B3: =Raw!B3 -> Inbound | C3: =Raw!C3 -> Gujarat | D3: =Raw!D3 -> Surat | E3: =IFERROR(INDEX(Location_Map!$B$2:$B$15,MATCH(C3,Location_Map!$A$2:$A$15,0)),"UNMAPPED") -> Gujarat | F3: =IFERROR(INDEX(Location_Map!$C$2:$C$15,MATCH(C3,Location_Map!$A$2:$A$15,0)),"UNMAPPED") -> West | G3: =IFERROR(INDEX(Location_Map!$B$2:$B$15,MATCH(D3,Location_Map!$A$2:$A$15,0)),"UNMAPPED") -> Gujarat | H3: =IFERROR(INDEX(Location_Map!$C$2:$C$15,MATCH(D3,Location_Map!$A$2:$A$15,0)),"UNMAPPED") -> West | I3: =Raw!E3 -> Finished Yarn | J3: =Raw!F3 -> 1.39 | K3: =DATE(LEFT(Raw!G3,4),MID(Raw!G3,6,2),MID(Raw!G3,9,2)) -> 45948 | L3: =DATE(LEFT(Raw!H3,4),MID(Raw!H3,6,2),MID(Raw!H3,9,2)) -> 45952 | M3: =DATE(LEFT(Raw!I3,4),MID(Raw!I3,6,2),MID(Raw!I3,9,2)) -> 45955 | N3: =DATE(LEFT(Raw!J3,4),MID(Raw!J3,6,2),MID(Raw!J3,9,2))+TIME(MID(Raw!J3,12,2),MID(Raw!J3,15,2),MID(Raw!J3,18,2)) -> 45952.25 | O3: =DATE(LEFT(Raw!K3,4),MID(Raw!K3,6,2),MID(Raw!K3,9,2))+TIME(MID(Raw!K3,12,2),MID(Raw!K3,15,2),MID(Raw!K3,18,2)) -> 45963.4 | P3: =L3-K3 -> 4 | Q3: =M3-L3 -> 3 | R3: =O3-N3 -> 11.15 | S3: =Raw!L3 -> 8.4 | T3: =O3-M3 -> 8.4 | U3: =IF(ABS(T3-S3)<0.01,"OK","MISMATCH") -> OK | V3: =Raw!M3 -> 1 | W3: =IF((S3>0)=(V3=1),"OK","MISMATCH") -> OK | X3: =_xlfn.IFS(S3<=0,"Early/On time",S3<=2,"Minor (up to 2 days)",S3<=5,"Moderate (2-5 days)",TRUE(),"Severe (over 5 days)") -> Severe (over 5 days) | Y3: =YEAR(K3)&"-"&TEXT(MONTH(K3),"00") -> 2025-10 | Z3: =C3&" → "&D3 -> Gujarat → Surat | AA3: =Raw!Q3 -> Delhivery | AB3: =Raw!R3 -> Yes | AC3: =Raw!S3 -> Returned | AD3: =Raw!N3 -> 1372.05 | AE3: =Raw!O3 -> 3099.03 | AF3: =Raw!P3 -> 931.95 | AG3: =AD3/J3 -> 987.08633
A4: =Raw!A4 -> SHP0003 | B4: =Raw!B4 -> Inbound | C4: =Raw!C4 -> Gujarat | D4: =Raw!D4 -> Surat | E4: =IFERROR(INDEX(Location_Map!$B$2:$B$15,MATCH(C4,Location_Map!$A$2:$A$15,0)),"UNMAPPED") -> Gujarat | F4: =IFERROR(INDEX(Location_Map!$C$2:$C$15,MATCH(C4,Location_Map!$A$2:$A$15,0)),"UNMAPPED") -> West | G4: =IFERROR(INDEX(Location_Map!$B$2:$B$15,MATCH(D4,Location_Map!$A$2:$A$15,0)),"UNMAPPED") -> Gujarat | H4: =IFERROR(INDEX(Location_Map!$C$2:$C$15,MATCH(D4,Location_Map!$A$2:$A$15,0)),"UNMAPPED") -> West | I4: =Raw!E4 -> Raw Yarn | J4: =Raw!F4 -> 6.53 | K4: =DATE(LEFT(Raw!G4,4),MID(Raw!G4,6,2),MID(Raw!G4,9,2)) -> 45841 | L4: =DATE(LEFT(Raw!H4,4),MID(Raw!H4,6,2),MID(Raw!H4,9,2)) -> 45842 | M4: =DATE(LEFT(Raw!I4,4),MID(Raw!I4,6,2),MID(Raw!I4,9,2)) -> 45847 | N4: =DATE(LEFT(Raw!J4,4),MID(Raw!J4,6,2),MID(Raw!J4,9,2))+TIME(MID(Raw!J4,12,2),MID(Raw!J4,15,2),MID(Raw!J4,18,2)) -> 45842.25 | O4: =DATE(LEFT(Raw!K4,4),MID(Raw!K4,6,2),MID(Raw!K4,9,2))+TIME(MID(Raw!K4,12,2),MID(Raw!K4,15,2),MID(Raw!K4,18,2)) -> 45849.7 | P4: =L4-K4 -> 1 | Q4: =M4-L4 -> 5 | R4: =O4-N4 -> 7.45 | S4: =Raw!L4 -> 2.7 | T4: =O4-M4 -> 2.7 | U4: =IF(ABS(T4-S4)<0.01,"OK","MISMATCH") -> OK | V4: =Raw!M4 -> 1 | W4: =IF((S4>0)=(V4=1),"OK","MISMATCH") -> OK | X4: =_xlfn.IFS(S4<=0,"Early/On time",S4<=2,"Minor (up to 2 days)",S4<=5,"Moderate (2-5 days)",TRUE(),"Severe (over 5 days)") -> Moderate (2-5 days) | Y4: =YEAR(K4)&"-"&TEXT(MONTH(K4),"00") -> 2025-07 | Z4: =C4&" → "&D4 -> Gujarat → Surat | AA4: =Raw!Q4 -> VRL Cargo | AB4: =Raw!R4 -> Yes | AC4: =Raw!S4 -> Returned | AD4: =Raw!N4 -> 4024.74 | AE4: =Raw!O4 -> 1185.8 | AF4: =Raw!P4 -> 1107.54 | AG4: =AD4/J4 -> 616.34609
A5: =Raw!A5 -> SHP0004 | B5: =Raw!B5 -> Outbound | C5: =Raw!C5 -> Surat | D5: =Raw!D5 -> Uttarakhand | E5: =IFERROR(INDEX(Location_Map!$B$2:$B$15,MATCH(C5,Location_Map!$A$2:$A$15,0)),"UNMAPPED") -> Gujarat | F5: =IFERROR(INDEX(Location_Map!$C$2:$C$15,MATCH(C5,Location_Map!$A$2:$A$15,0)),"UNMAPPED") -> West | G5: =IFERROR(INDEX(Location_Map!$B$2:$B$15,MATCH(D5,Location_Map!$A$2:$A$15,0)),"UNMAPPED") -> Uttarakhand | H5: =IFERROR(INDEX(Location_Map!$C$2:$C$15,MATCH(D5,Location_Map!$A$2:$A$15,0)),"UNMAPPED") -> North | I5: =Raw!E5 -> Raw Yarn | J5: =Raw!F5 -> 4.24 | K5: =DATE(LEFT(Raw!G5,4),MID(Raw!G5,6,2),MID(Raw!G5,9,2)) -> 45677 | L5: =DATE(LEFT(Raw!H5,4),MID(Raw!H5,6,2),MID(Raw!H5,9,2)) -> 45681 | M5: =DATE(LEFT(Raw!I5,4),MID(Raw!I5,6,2),MID(Raw!I5,9,2)) -> 45686 | N5: =DATE(LEFT(Raw!J5,4),MID(Raw!J5,6,2),MID(Raw!J5,9,2))+TIME(MID(Raw!J5,12,2),MID(Raw!J5,15,2),MID(Raw!J5,18,2)) -> 45681.333 | O5: =DATE(LEFT(Raw!K5,4),MID(Raw!K5,6,2),MID(Raw!K5,9,2))+TIME(MID(Raw!K5,12,2),MID(Raw!K5,15,2),MID(Raw!K5,18,2)) -> 45685.7 | P5: =L5-K5 -> 4 | Q5: =M5-L5 -> 5 | R5: =O5-N5 -> 4.3666667 | S5: =Raw!L5 -> -0.3 | T5: =O5-M5 -> -0.3 | U5: =IF(ABS(T5-S5)<0.01,"OK","MISMATCH") -> OK | V5: =Raw!M5 -> 0 | W5: =IF((S5>0)=(V5=1),"OK","MISMATCH") -> OK | X5: =_xlfn.IFS(S5<=0,"Early/On time",S5<=2,"Minor (up to 2 days)",S5<=5,"Moderate (2-5 days)",TRUE(),"Severe (over 5 days)") -> Early/On time | Y5: =YEAR(K5)&"-"&TEXT(MONTH(K5),"00") -> 2025-01 | Z5: =C5&" → "&D5 -> Surat → Uttarakhand | AA5: =Raw!Q5 -> Delhivery | AB5: =Raw!R5 -> No | AC5: =Raw!S5 -> Expedited | AD5: =Raw!N5 -> 2914.33 | AE5: =Raw!O5 -> 1390.69 | AF5: =Raw!P5 -> 1184.23 | AG5: =AD5/J5 -> 687.34198
A6: =Raw!A6 -> SHP0005 | B6: =Raw!B6 -> Inbound | C6: =Raw!C6 -> Punjab | D6: =Raw!D6 -> Surat | E6: =IFERROR(INDEX(Location_Map!$B$2:$B$15,MATCH(C6,Location_Map!$A$2:$A$15,0)),"UNMAPPED") -> Punjab | F6: =IFERROR(INDEX(Location_Map!$C$2:$C$15,MATCH(C6,Location_Map!$A$2:$A$15,0)),"UNMAPPED") -> North | G6: =IFERROR(INDEX(Location_Map!$B$2:$B$15,MATCH(D6,Location_Map!$A$2:$A$15,0)),"UNMAPPED") -> Gujarat | H6: =IFERROR(INDEX(Location_Map!$C$2:$C$15,MATCH(D6,Location_Map!$A$2:$A$15,0)),"UNMAPPED") -> West | I6: =Raw!E6 -> Raw Yarn | J6: =Raw!F6 -> 9.36 | K6: =DATE(LEFT(Raw!G6,4),MID(Raw!G6,6,2),MID(Raw!G6,9,2)) -> 45694 | L6: =DATE(LEFT(Raw!H6,4),MID(Raw!H6,6,2),MID(Raw!H6,9,2)) -> 45696 | M6: =DATE(LEFT(Raw!I6,4),MID(Raw!I6,6,2),MID(Raw!I6,9,2)) -> 45700 | N6: =DATE(LEFT(Raw!J6,4),MID(Raw!J6,6,2),MID(Raw!J6,9,2))+TIME(MID(Raw!J6,12,2),MID(Raw!J6,15,2),MID(Raw!J6,18,2)) -> 45696.083 | O6: =DATE(LEFT(Raw!K6,4),MID(Raw!K6,6,2),MID(Raw!K6,9,2))+TIME(MID(Raw!K6,12,2),MID(Raw!K6,15,2),MID(Raw!K6,18,2)) -> 45701.3 | P6: =L6-K6 -> 2 | Q6: =M6-L6 -> 4 | R6: =O6-N6 -> 5.2166667 | S6: =Raw!L6 -> 1.3 | T6: =O6-M6 -> 1.3 | U6: =IF(ABS(T6-S6)<0.01,"OK","MISMATCH") -> OK | V6: =Raw!M6 -> 1 | W6: =IF((S6>0)=(V6=1),"OK","MISMATCH") -> OK | X6: =_xlfn.IFS(S6<=0,"Early/On time",S6<=2,"Minor (up to 2 days)",S6<=5,"Moderate (2-5 days)",TRUE(),"Severe (over 5 days)") -> Minor (up to 2 days) | Y6: =YEAR(K6)&"-"&TEXT(MONTH(K6),"00") -> 2025-02 | Z6: =C6&" → "&D6 -> Punjab → Surat | AA6: =Raw!Q6 -> VRL Cargo | AB6: =Raw!R6 -> No | AC6: =Raw!S6 -> Held at warehouse | AD6: =Raw!N6 -> 5480.42 | AE6: =Raw!O6 -> 1831.77 | AF6: =Raw!P6 -> 1067.7 | AG6: =AD6/J6 -> 585.51496
A7: =Raw!A7 -> SHP0006 | B7: =Raw!B7 -> Inbound | C7: =Raw!C7 -> Chennai | D7: =Raw!D7 -> Surat | E7: =IFERROR(INDEX(Location_Map!$B$2:$B$15,MATCH(C7,Location_Map!$A$2:$A$15,0)),"UNMAPPED") -> Tamil Nadu | F7: =IFERROR(INDEX(Location_Map!$C$2:$C$15,MATCH(C7,Location_Map!$A$2:$A$15,0)),"UNMAPPED") -> South | G7: =IFERROR(INDEX(Location_Map!$B$2:$B$15,MATCH(D7,Location_Map!$A$2:$A$15,0)),"UNMAPPED") -> Gujarat | H7: =IFERROR(INDEX(Location_Map!$C$2:$C$15,MATCH(D7,Location_Map!$A$2:$A$15,0)),"UNMAPPED") -> West | I7: =Raw!E7 -> Semi-Processed Yarn | J7: =Raw!F7 -> 1.59 | K7: =DATE(LEFT(Raw!G7,4),MID(Raw!G7,6,2),MID(Raw!G7,9,2)) -> 45910 | L7: =DATE(LEFT(Raw!H7,4),MID(Raw!H7,6,2),MID(Raw!H7,9,2)) -> 45912 | M7: =DATE(LEFT(Raw!I7,4),MID(Raw!I7,6,2),MID(Raw!I7,9,2)) -> 45915 | N7: =DATE(LEFT(Raw!J7,4),MID(Raw!J7,6,2),MID(Raw!J7,9,2))+TIME(MID(Raw!J7,12,2),MID(Raw!J7,15,2),MID(Raw!J7,18,2)) -> 45912.333 | O7: =DATE(LEFT(Raw!K7,4),MID(Raw!K7,6,2),MID(Raw!K7,9,2))+TIME(MID(Raw!K7,12,2),MID(Raw!K7,15,2),MID(Raw!K7,18,2)) -> 45918.2 | P7: =L7-K7 -> 2 | Q7: =M7-L7 -> 3 | R7: =O7-N7 -> 5.8666667 | S7: =Raw!L7 -> 3.2 | T7: =O7-M7 -> 3.2 | U7: =IF(ABS(T7-S7)<0.01,"OK","MISMATCH") -> OK | V7: =Raw!M7 -> 1 | W7: =IF((S7>0)=(V7=1),"OK","MISMATCH") -> OK | X7: =_xlfn.IFS(S7<=0,"Early/On time",S7<=2,"Minor (up to 2 days)",S7<=5,"Moderate (2-5 days)",TRUE(),"Severe (over 5 days)") -> Moderate (2-5 days) | Y7: =YEAR(K7)&"-"&TEXT(MONTH(K7),"00") -> 2025-09 | Z7: =C7&" → "&D7 -> Chennai → Surat | AA7: =Raw!Q7 -> GATI Logistics | AB7: =Raw!R7 -> Yes | AC7: =Raw!S7 -> Damaged | AD7: =Raw!N7 -> 2304.02 | AE7: =Raw!O7 -> 2306.16 | AF7: =Raw!P7 -> 1070.44 | AG7: =AD7/J7 -> 1449.0692
A8: =Raw!A8 -> SHP0007 | B8: =Raw!B8 -> Inbound | C8: =Raw!C8 -> Punjab | D8: =Raw!D8 -> Surat | E8: =IFERROR(INDEX(Location_Map!$B$2:$B$15,MATCH(C8,Location_Map!$A$2:$A$15,0)),"UNMAPPED") -> Punjab | F8: =IFERROR(INDEX(Location_Map!$C$2:$C$15,MATCH(C8,Location_Map!$A$2:$A$15,0)),"UNMAPPED") -> North | G8: =IFERROR(INDEX(Location_Map!$B$2:$B$15,MATCH(D8,Location_Map!$A$2:$A$15,0)),"UNMAPPED") -> Gujarat | H8: =IFERROR(INDEX(Location_Map!$C$2:$C$15,MATCH(D8,Location_Map!$A$2:$A$15,0)),"UNMAPPED") -> West | I8: =Raw!E8 -> Finished Yarn | J8: =Raw!F8 -> 10.9 | K8: =DATE(LEFT(Raw!G8,4),MID(Raw!G8,6,2),MID(Raw!G8,9,2)) -> 45946 | L8: =DATE(LEFT(Raw!H8,4),MID(Raw!H8,6,2),MID(Raw!H8,9,2)) -> 45950 | M8: =DATE(LEFT(Raw!I8,4),MID(Raw!I8,6,2),MID(Raw!I8,9,2)) -> 45956 | N8: =DATE(LEFT(Raw!J8,4),MID(Raw!J8,6,2),MID(Raw!J8,9,2))+TIME(MID(Raw!J8,12,2),MID(Raw!J8,15,2),MID(Raw!J8,18,2)) -> 45950.167 | O8: =DATE(LEFT(Raw!K8,4),MID(Raw!K8,6,2),MID(Raw!K8,9,2))+TIME(MID(Raw!K8,12,2),MID(Raw!K8,15,2),MID(Raw!K8,18,2)) -> 45960.3 | P8: =L8-K8 -> 4 | Q8: =M8-L8 -> 6 | R8: =O8-N8 -> 10.133333 | S8: =Raw!L8 -> 4.3 | T8: =O8-M8 -> 4.3 | U8: =IF(ABS(T8-S8)<0.01,"OK","MISMATCH") -> OK | V8: =Raw!M8 -> 1 | W8: =IF((S8>0)=(V8=1),"OK","MISMATCH") -> OK | X8: =_xlfn.IFS(S8<=0,"Early/On time",S8<=2,"Minor (up to 2 days)",S8<=5,"Moderate (2-5 days)",TRUE(),"Severe (over 5 days)") -> Moderate (2-5 days) | Y8: =YEAR(K8)&"-"&TEXT(MONTH(K8),"00") -> 2025-10 | Z8: =C8&" → "&D8 -> Punjab → Surat | AA8: =Raw!Q8 -> BlueDart | AB8: =Raw!R8 -> Yes | AC8: =Raw!S8 -> Damaged | AD8: =Raw!N8 -> 7761.59 | AE8: =Raw!O8 -> 2104 | AF8: =Raw!P8 -> 796.27 | AG8: =AD8/J8 -> 712.07248
A9: =Raw!A9 -> SHP0008 | B9: =Raw!B9 -> Inbound | C9: =Raw!C9 -> Rajasthan | D9: =Raw!D9 -> Surat | E9: =IFERROR(INDEX(Location_Map!$B$2:$B$15,MATCH(C9,Location_Map!$A$2:$A$15,0)),"UNMAPPED") -> Rajasthan | F9: =IFERROR(INDEX(Location_Map!$C$2:$C$15,MATCH(C9,Location_Map!$A$2:$A$15,0)),"UNMAPPED") -> North | G9: =IFERROR(INDEX(Location_Map!$B$2:$B$15,MATCH(D9,Location_Map!$A$2:$A$15,0)),"UNMAPPED") -> Gujarat | H9: =IFERROR(INDEX(Location_Map!$C$2:$C$15,MATCH(D9,Location_Map!$A$2:$A$15,0)),"UNMAPPED") -> West | I9: =Raw!E9 -> Raw Yarn | J9: =Raw!F9 -> 4.14 | K9: =DATE(LEFT(Raw!G9,4),MID(Raw!G9,6,2),MID(Raw!G9,9,2)) -> 45662 | L9: =DATE(LEFT(Raw!H9,4),MID(Raw!H9,6,2),MID(Raw!H9,9,2)) -> 45664 | M9: =DATE(LEFT(Raw!I9,4),MID(Raw!I9,6,2),MID(Raw!I9,9,2)) -> 45666 | N9: =DATE(LEFT(Raw!J9,4),MID(Raw!J9,6,2),MID(Raw!J9,9,2))+TIME(MID(Raw!J9,12,2),MID(Raw!J9,15,2),MID(Raw!J9,18,2)) -> 45664.25 | O9: =DATE(LEFT(Raw!K9,4),MID(Raw!K9,6,2),MID(Raw!K9,9,2))+TIME(MID(Raw!K9,12,2),MID(Raw!K9,15,2),MID(Raw!K9,18,2)) -> 45666.4 | P9: =L9-K9 -> 2 | Q9: =M9-L9 -> 2 | R9: =O9-N9 -> 2.15 | S9: =Raw!L9 -> 0.4 | T9: =O9-M9 -> 0.4 | U9: =IF(ABS(T9-S9)<0.01,"OK","MISMATCH") -> OK | V9: =Raw!M9 -> 1 | W9: =IF((S9>0)=(V9=1),"OK","MISMATCH") -> OK | X9: =_xlfn.IFS(S9<=0,"Early/On time",S9<=2,"Minor (up to 2 days)",S9<=5,"Moderate (2-5 days)",TRUE(),"Severe (over 5 days)") -> Minor (up to 2 days) | Y9: =YEAR(K9)&"-"&TEXT(MONTH(K9),"00") -> 2025-01 | Z9: =C9&" → "&D9 -> Rajasthan → Surat | AA9: =Raw!Q9 -> Delhivery | AB9: =Raw!R9 -> No | AC9: =Raw!S9 -> Returned | AD9: =Raw!N9 -> 1775.62 | AE9: =Raw!O9 -> 1795.37 | AF9: =Raw!P9 -> 1211.34 | AG9: =AD9/J9 -> 428.89372
A10: =Raw!A10 -> SHP0009 | B10: =Raw!B10 -> Outbound | C10: =Raw!C10 -> Surat | D10: =Raw!D10 -> West Bengal | E10: =IFERROR(INDEX(Location_Map!$B$2:$B$15,MATCH(C10,Location_Map!$A$2:$A$15,0)),"UNMAPPED") -> Gujarat | F10: =IFERROR(INDEX(Location_Map!$C$2:$C$15,MATCH(C10,Location_Map!$A$2:$A$15,0)),"UNMAPPED") -> West | G10: =IFERROR(INDEX(Location_Map!$B$2:$B$15,MATCH(D10,Location_Map!$A$2:$A$15,0)),"UNMAPPED") -> West Bengal | H10: =IFERROR(INDEX(Location_Map!$C$2:$C$15,MATCH(D10,Location_Map!$A$2:$A$15,0)),"UNMAPPED") -> East | I10: =Raw!E10 -> Finished Yarn | J10: =Raw!F10 -> 16.01 | K10: =DATE(LEFT(Raw!G10,4),MID(Raw!G10,6,2),MID(Raw!G10,9,2)) -> 45839 | L10: =DATE(LEFT(Raw!H10,4),MID(Raw!H10,6,2),MID(Raw!H10,9,2)) -> 45843 | M10: =DATE(LEFT(Raw!I10,4),MID(Raw!I10,6,2),MID(Raw!I10,9,2)) -> 45846 | N10: =DATE(LEFT(Raw!J10,4),MID(Raw!J10,6,2),MID(Raw!J10,9,2))+TIME(MID(Raw!J10,12,2),MID(Raw!J10,15,2),MID(Raw!J10,18,2)) -> 45843.042 | O10: =DATE(LEFT(Raw!K10,4),MID(Raw!K10,6,2),MID(Raw!K10,9,2))+TIME(MID(Raw!K10,12,2),MID(Raw!K10,15,2),MID(Raw!K10,18,2)) -> 45845 | P10: =L10-K10 -> 4 | Q10: =M10-L10 -> 3 | R10: =O10-N10 -> 1.9583333 | S10: =Raw!L10 -> -1 | T10: =O10-M10 -> -1 | U10: =IF(ABS(T10-S10)<0.01,"OK","MISMATCH") -> OK | V10: =Raw!M10 -> 0 | W10: =IF((S10>0)=(V10=1),"OK","MISMATCH") -> OK | X10: =_xlfn.IFS(S10<=0,"Early/On time",S10<=2,"Minor (up to 2 days)",S10<=5,"Moderate (2-5 days)",TRUE(),"Severe (over 5 days)") -> Early/On time | Y10: =YEAR(K10)&"-"&TEXT(MONTH(K10),"00") -> 2025-07 | Z10: =C10&" → "&D10 -> Surat → West Bengal | AA10: =Raw!Q10 -> VRL Cargo | AB10: =Raw!R10 -> Yes | AC10: =Raw!S10 -> Normal | AD10: =Raw!N10 -> 5853.01 | AE10: =Raw!O10 -> 3918.42 | AF10: =Raw!P10 -> 1137.56 | AG10: =AD10/J10 -> 365.58463
A11: =Raw!A11 -> SHP0010 | B11: =Raw!B11 -> Outbound | C11: =Raw!C11 -> Surat | D11: =Raw!D11 -> Kerala | E11: =IFERROR(INDEX(Location_Map!$B$2:$B$15,MATCH(C11,Location_Map!$A$2:$A$15,0)),"UNMAPPED") -> Gujarat | F11: =IFERROR(INDEX(Location_Map!$C$2:$C$15,MATCH(C11,Location_Map!$A$2:$A$15,0)),"UNMAPPED") -> West | G11: =IFERROR(INDEX(Location_Map!$B$2:$B$15,MATCH(D11,Location_Map!$A$2:$A$15,0)),"UNMAPPED") -> Kerala | H11: =IFERROR(INDEX(Location_Map!$C$2:$C$15,MATCH(D11,Location_Map!$A$2:$A$15,0)),"UNMAPPED") -> South | I11: =Raw!E11 -> Raw Yarn | J11: =Raw!F11 -> 17.86 | K11: =DATE(LEFT(Raw!G11,4),MID(Raw!G11,6,2),MID(Raw!G11,9,2)) -> 45799 | L11: =DATE(LEFT(Raw!H11,4),MID(Raw!H11,6,2),MID(Raw!H11,9,2)) -> 45800 | M11: =DATE(LEFT(Raw!I11,4),MID(Raw!I11,6,2),MID(Raw!I11,9,2)) -> 45804 | N11: =DATE(LEFT(Raw!J11,4),MID(Raw!J11,6,2),MID(Raw!J11,9,2))+TIME(MID(Raw!J11,12,2),MID(Raw!J11,15,2),MID(Raw!J11,18,2)) -> 45799.792 | O11: =DATE(LEFT(Raw!K11,4),MID(Raw!K11,6,2),MID(Raw!K11,9,2))+TIME(MID(Raw!K11,12,2),MID(Raw!K11,15,2),MID(Raw!K11,18,2)) -> 45809.3 | P11: =L11-K11 -> 1 | Q11: =M11-L11 -> 4 | R11: =O11-N11 -> 9.5083333 | S11: =Raw!L11 -> 5.3 | T11: =O11-M11 -> 5.3 | U11: =IF(ABS(T11-S11)<0.01,"OK","MISMATCH") -> OK | V11: =Raw!M11 -> 1 | W11: =IF((S11>0)=(V11=1),"OK","MISMATCH") -> OK | X11: =_xlfn.IFS(S11<=0,"Early/On time",S11<=2,"Minor (up to 2 days)",S11<=5,"Moderate (2-5 days)",TRUE(),"Severe (over 5 days)") -> Severe (over 5 days) | Y11: =YEAR(K11)&"-"&TEXT(MONTH(K11),"00") -> 2025-05 | Z11: =C11&" → "&D11 -> Surat → Kerala | AA11: =Raw!Q11 -> VRL Cargo | AB11: =Raw!R11 -> Yes | AC11: =Raw!S11 -> Damaged | AD11: =Raw!N11 -> 8145.26 | AE11: =Raw!O11 -> 2024.27 | AF11: =Raw!P11 -> 540.43 | AG11: =AD11/J11 -> 456.06159
A12: =Raw!A12 -> SHP0011 | B12: =Raw!B12 -> Inbound | C12: =Raw!C12 -> Punjab | D12: =Raw!D12 -> Surat | E12: =IFERROR(INDEX(Location_Map!$B$2:$B$15,MATCH(C12,Location_Map!$A$2:$A$15,0)),"UNMAPPED") -> Punjab | F12: =IFERROR(INDEX(Location_Map!$C$2:$C$15,MATCH(C12,Location_Map!$A$2:$A$15,0)),"UNMAPPED") -> North | G12: =IFERROR(INDEX(Location_Map!$B$2:$B$15,MATCH(D12,Location_Map!$A$2:$A$15,0)),"UNMAPPED") -> Gujarat | H12: =IFERROR(INDEX(Location_Map!$C$2:$C$15,MATCH(D12,Location_Map!$A$2:$A$15,0)),"UNMAPPED") -> West | I12: =Raw!E12 -> Raw Yarn | J12: =Raw!F12 -> 14.5 | K12: =DATE(LEFT(Raw!G12,4),MID(Raw!G12,6,2),MID(Raw!G12,9,2)) -> 45691 | L12: =DATE(LEFT(Raw!H12,4),MID(Raw!H12,6,2),MID(Raw!H12,9,2)) -> 45693 | M12: =DATE(LEFT(Raw!I12,4),MID(Raw!I12,6,2),MID(Raw!I12,9,2)) -> 45697 | N12: =DATE(LEFT(Raw!J12,4),MID(Raw!J12,6,2),MID(Raw!J12,9,2))+TIME(MID(Raw!J12,12,2),MID(Raw!J12,15,2),MID(Raw!J12,18,2)) -> 45692.917 | O12: =DATE(LEFT(Raw!K12,4),MID(Raw!K12,6,2),MID(Raw!K12,9,2))+TIME(MID(Raw!K12,12,2),MID(Raw!K12,15,2),MID(Raw!K12,18,2)) -> 45699.3 | P12: =L12-K12 -> 2 | Q12: =M12-L12 -> 4 | R12: =O12-N12 -> 6.3833333 | S12: =Raw!L12 -> 2.3 | T12: =O12-M12 -> 2.3 | U12: =IF(ABS(T12-S12)<0.01,"OK","MISMATCH") -> OK | V12: =Raw!M12 -> 1 | W12: =IF((S12>0)=(V12=1),"OK","MISMATCH") -> OK | X12: =_xlfn.IFS(S12<=0,"Early/On time",S12<=2,"Minor (up to 2 days)",S12<=5,"Moderate (2-5 days)",TRUE(),"Severe (over 5 days)") -> Moderate (2-5 days) | Y12: =YEAR(K12)&"-"&TEXT(MONTH(K12),"00") -> 2025-02 | Z12: =C12&" → "&D12 -> Punjab → Surat | AA12: =Raw!Q12 -> BlueDart | AB12: =Raw!R12 -> No | AC12: =Raw!S12 -> Expedited | AD12: =Raw!N12 -> 8171.89 | AE12: =Raw!O12 -> 1557.33 | AF12: =Raw!P12 -> 1104.42 | AG12: =AD12/J12 -> 563.57862
A13: =Raw!A13 -> SHP0012 | B13: =Raw!B13 -> Outbound | C13: =Raw!C13 -> Surat | D13: =Raw!D13 -> Madhya Pradesh | E13: =IFERROR(INDEX(Location_Map!$B$2:$B$15,MATCH(C13,Location_Map!$A$2:$A$15,0)),"UNMAPPED") -> Gujarat | F13: =IFERROR(INDEX(Location_Map!$C$2:$C$15,MATCH(C13,Location_Map!$A$2:$A$15,0)),"UNMAPPED") -> West | G13: =IFERROR(INDEX(Location_Map!$B$2:$B$15,MATCH(D13,Location_Map!$A$2:$A$15,0)),"UNMAPPED") -> Madhya Pradesh | H13: =IFERROR(INDEX(Location_Map!$C$2:$C$15,MATCH(D13,Location_Map!$A$2:$A$15,0)),"UNMAPPED") -> Central | I13: =Raw!E13 -> Finished Yarn | J13: =Raw!F13 -> 11.26 | K13: =DATE(LEFT(Raw!G13,4),MID(Raw!G13,6,2),MID(Raw!G13,9,2)) -> 45718 | L13: =DATE(LEFT(Raw!H13,4),MID(Raw!H13,6,2),MID(Raw!H13,9,2)) -> 45722 | M13: =DATE(LEFT(Raw!I13,4),MID(Raw!I13,6,2),MID(Raw!I13,9,2)) -> 45726 | N13: =DATE(LEFT(Raw!J13,4),MID(Raw!J13,6,2),MID(Raw!J13,9,2))+TIME(MID(Raw!J13,12,2),MID(Raw!J13,15,2),MID(Raw!J13,18,2)) -> 45721.875 | O13: =DATE(LEFT(Raw!K13,4),MID(Raw!K13,6,2),MID(Raw!K13,9,2))+TIME(MID(Raw!K13,12,2),MID(Raw!K13,15,2),MID(Raw!K13,18,2)) -> 45727.1 | P13: =L13-K13 -> 4 | Q13: =M13-L13 -> 4 | R13: =O13-N13 -> 5.225 | S13: =Raw!L13 -> 1.1 | T13: =O13-M13 -> 1.1 | U13: =IF(ABS(T13-S13)<0.01,"OK","MISMATCH") -> OK | V13: =Raw!M13 -> 1 | W13: =IF((S13>0)=(V13=1),"OK","MISMATCH") -> OK | X13: =_xlfn.IFS(S13<=0,"Early/On time",S13<=2,"Minor (up to 2 days)",S13<=5,"Moderate (2-5 days)",TRUE(),"Severe (over 5 days)") -> Minor (up to 2 days) | Y13: =YEAR(K13)&"-"&TEXT(MONTH(K13),"00") -> 2025-03 | Z13: =C13&" → "&D13 -> Surat → Madhya Pradesh | AA13: =Raw!Q13 -> VRL Cargo | AB13: =Raw!R13 -> Yes | AC13: =Raw!S13 -> Expedited | AD13: =Raw!N13 -> 5508.07 | AE13: =Raw!O13 -> 4232.48 | AF13: =Raw!P13 -> 1133.4 | AG13: =AD13/J13 -> 489.1714
... A1001: =Raw!A1001 -> SHP1000 | B1001: =Raw!B1001 -> Inbound | C1001: =Raw!C1001 -> Gujarat | D1001: =Raw!D1001 -> Surat | E1001: =IFERROR(INDEX(Location_Map!$B$2:$B$15,MATCH(C1001,Location_Map!$A$2:$A$15,0)),"UNMAPPED") -> Gujarat | F1001: =IFERROR(INDEX(Location_Map!$C$2:$C$15,MATCH(C1001,Location_Map!$A$2:$A$15,0)),"UNMAPPED") -> West | G1001: =IFERROR(INDEX(Location_Map!$B$2:$B$15,MATCH(D1001,Location_Map!$A$2:$A$15,0)),"UNMAPPED") -> Gujarat | H1001: =IFERROR(INDEX(Location_Map!$C$2:$C$15,MATCH(D1001,Location_Map!$A$2:$A$15,0)),"UNMAPPED") -> West | I1001: =Raw!E1001 -> Semi-Processed Yarn | J1001: =Raw!F1001 -> 14.07 | K1001: =DATE(LEFT(Raw!G1001,4),MID(Raw!G1001,6,2),MID(Raw!G1001,9,2)) -> 45939 | L1001: =DATE(LEFT(Raw!H1001,4),MID(Raw!H1001,6,2),MID(Raw!H1001,9,2)) -> 45942 | M1001: =DATE(LEFT(Raw!I1001,4),MID(Raw!I1001,6,2),MID(Raw!I1001,9,2)) -> 45947 | N1001: =DATE(LEFT(Raw!J1001,4),MID(Raw!J1001,6,2),MID(Raw!J1001,9,2))+TIME(MID(Raw!J1001,12,2),MID(Raw!J1001,15,2),MID(Raw!J1001,18,2)) -> 45941.958 | O1001: =DATE(LEFT(Raw!K1001,4),MID(Raw!K1001,6,2),MID(Raw!K1001,9,2))+TIME(MID(Raw!K1001,12,2),MID(Raw!K1001,15,2),MID(Raw!K1001,18,2)) -> 45952.4 | P1001: =L1001-K1001 -> 3 | Q1001: =M1001-L1001 -> 5 | R1001: =O1001-N1001 -> 10.441667 | S1001: =Raw!L1001 -> 5.4 | T1001: =O1001-M1001 -> 5.4 | U1001: =IF(ABS(T1001-S1001)<0.01,"OK","MISMATCH") -> OK | V1001: =Raw!M1001 -> 1 | W1001: =IF((S1001>0)=(V1001=1),"OK","MISMATCH") -> OK | X1001: =_xlfn.IFS(S1001<=0,"Early/On time",S1001<=2,"Minor (up to 2 days)",S1001<=5,"Moderate (2-5 days)",TRUE(),"Severe (over 5 days)") -> Severe (over 5 days) | Y1001: =YEAR(K1001)&"-"&TEXT(MONTH(K1001),"00") -> 2025-10 | Z1001: =C1001&" → "&D1001 -> Gujarat → Surat | AA1001: =Raw!Q1001 -> TCI Express | AB1001: =Raw!R1001 -> Yes | AC1001: =Raw!S1001 -> Returned | AD1001: =Raw!N1001 -> 5637.64 | AE1001: =Raw!O1001 -> 4671.39 | AF1001: =Raw!P1001 -> 887.07 | AG1001: =AD1001/J1001 -> 400.68515

Sheet Location_Map
A1: Place (as in data) | B1: State | C1: Region | E1: Why this sheet exists
A2: Surat | B2: Gujarat | C2: West | E2: source_city and destination_city mix cities (Surat, Mumbai, Jaipur, Chennai) with whole states (Rajasthan, Kerala). This table maps every value to one state and region so they can be compared like for like.
A3: Gujarat | B3: Gujarat | C3: West
A4: Mumbai | B4: Maharashtra | C4: West
A5: Rajasthan | B5: Rajasthan | C5: North
A6: Jaipur | B6: Rajasthan | C6: North
A7: Punjab | B7: Punjab | C7: North
A8: Uttar Pradesh | B8: Uttar Pradesh | C8: North
A9: Uttarakhand | B9: Uttarakhand | C9: North
A10: Madhya Pradesh | B10: Madhya Pradesh | C10: Central
A11: Chennai | B11: Tamil Nadu | C11: South
A12: Kerala | B12: Kerala | C12: South
A13: Karnataka | B13: Karnataka | C13: South
A14: West Bengal | B14: West Bengal | C14: East
A15: Assam | B15: Assam | C15: North-East

Sheet Raw
A1: shipment_id | B1: shipment_type | C1: source_city | D1: destination_city | E1: material_type | F1: quantity_tonnes | G1: booking_date | H1: scheduled_departure | I1: scheduled_arrival | J1: actual_departure | K1: actual_arrival | L1: delay_days | M1: delay_flag | N1: shipping_cost | O1: expedite_surcharge | P1: stockout_cost_per_tonne | Q1: carrier | R1: temperature_sensitive | S1: remarks
A2: SHP0001 | B2: Outbound | C2: Surat | D2: Mumbai | E2: Finished Yarn | F2: 8.12 | G2: 2025-10-13 | H2: 2025-10-16 | I2: 2025-10-22 | J2: 2025-10-16 01:00:00 | K2: 2025-10-21 00:00:00 | L2: -1 | M2: 0 | N2: 3889.18 | O2: 3404.46 | P2: 1208.07 | Q2: BlueDart | R2: Yes | S2: Expedited
A3: SHP0002 | B3: Inbound | C3: Gujarat | D3: Surat | E3: Finished Yarn | F3: 1.39 | G3: 2025-10-18 | H3: 2025-10-22 | I3: 2025-10-25 | J3: 2025-10-22 06:00:00 | K3: 2025-11-02 09:36:00 | L3: 8.4 | M3: 1 | N3: 1372.05 | O3: 3099.03 | P3: 931.95 | Q3: Delhivery | R3: Yes | S3: Returned
A4: SHP0003 | B4: Inbound | C4: Gujarat | D4: Surat | E4: Raw Yarn | F4: 6.53 | G4: 2025-07-03 | H4: 2025-07-04 | I4: 2025-07-09 | J4: 2025-07-04 06:00:00 | K4: 2025-07-11 16:48:00 | L4: 2.7 | M4: 1 | N4: 4024.74 | O4: 1185.8 | P4: 1107.54 | Q4: VRL Cargo | R4: Yes | S4: Returned
A5: SHP0004 | B5: Outbound | C5: Surat | D5: Uttarakhand | E5: Raw Yarn | F5: 4.24 | G5: 2025-01-20 | H5: 2025-01-24 | I5: 2025-01-29 | J5: 2025-01-24 08:00:00 | K5: 2025-01-28 16:48:00 | L5: -0.3 | M5: 0 | N5: 2914.33 | O5: 1390.69 | P5: 1184.23 | Q5: Delhivery | R5: No | S5: Expedited
A6: SHP0005 | B6: Inbound | C6: Punjab | D6: Surat | E6: Raw Yarn | F6: 9.36 | G6: 2025-02-06 | H6: 2025-02-08 | I6: 2025-02-12 | J6: 2025-02-08 02:00:00 | K6: 2025-02-13 07:12:00 | L6: 1.3 | M6: 1 | N6: 5480.42 | O6: 1831.77 | P6: 1067.7 | Q6: VRL Cargo | R6: No | S6: Held at warehouse
A7: SHP0006 | B7: Inbound | C7: Chennai | D7: Surat | E7: Semi-Processed Yarn | F7: 1.59 | G7: 2025-09-10 | H7: 2025-09-12 | I7: 2025-09-15 | J7: 2025-09-12 08:00:00 | K7: 2025-09-18 04:48:00 | L7: 3.2 | M7: 1 | N7: 2304.02 | O7: 2306.16 | P7: 1070.44 | Q7: GATI Logistics | R7: Yes | S7: Damaged
A8: SHP0007 | B8: Inbound | C8: Punjab | D8: Surat | E8: Finished Yarn | F8: 10.9 | G8: 2025-10-16 | H8: 2025-10-20 | I8: 2025-10-26 | J8: 2025-10-20 04:00:00 | K8: 2025-10-30 07:12:00 | L8: 4.3 | M8: 1 | N8: 7761.59 | O8: 2104 | P8: 796.27 | Q8: BlueDart | R8: Yes | S8: Damaged
A9: SHP0008 | B9: Inbound | C9: Rajasthan | D9: Surat | E9: Raw Yarn | F9: 4.14 | G9: 2025-01-05 | H9: 2025-01-07 | I9: 2025-01-09 | J9: 2025-01-07 06:00:00 | K9: 2025-01-09 09:36:00 | L9: 0.4 | M9: 1 | N9: 1775.62 | O9: 1795.37 | P9: 1211.34 | Q9: Delhivery | R9: No | S9: Returned
A10: SHP0009 | B10: Outbound | C10: Surat | D10: West Bengal | E10: Finished Yarn | F10: 16.01 | G10: 2025-07-01 | H10: 2025-07-05 | I10: 2025-07-08 | J10: 2025-07-05 01:00:00 | K10: 2025-07-07 00:00:00 | L10: -1 | M10: 0 | N10: 5853.01 | O10: 3918.42 | P10: 1137.56 | Q10: VRL Cargo | R10: Yes | S10: Normal
A11: SHP0010 | B11: Outbound | C11: Surat | D11: Kerala | E11: Raw Yarn | F11: 17.86 | G11: 2025-05-22 | H11: 2025-05-23 | I11: 2025-05-27 | J11: 2025-05-22 19:00:00 | K11: 2025-06-01 07:12:00 | L11: 5.3 | M11: 1 | N11: 8145.26 | O11: 2024.27 | P11: 540.43 | Q11: VRL Cargo | R11: Yes | S11: Damaged
A12: SHP0011 | B12: Inbound | C12: Punjab | D12: Surat | E12: Raw Yarn | F12: 14.5 | G12: 2025-02-03 | H12: 2025-02-05 | I12: 2025-02-09 | J12: 2025-02-04 22:00:00 | K12: 2025-02-11 07:12:00 | L12: 2.3 | M12: 1 | N12: 8171.89 | O12: 1557.33 | P12: 1104.42 | Q12: BlueDart | R12: No | S12: Expedited
A13: SHP0012 | B13: Outbound | C13: Surat | D13: Madhya Pradesh | E13: Finished Yarn | F13: 11.26 | G13: 2025-03-02 | H13: 2025-03-06 | I13: 2025-03-10 | J13: 2025-03-05 21:00:00 | K13: 2025-03-11 02:24:00 | L13: 1.1 | M13: 1 | N13: 5508.07 | O13: 4232.48 | P13: 1133.4 | Q13: VRL Cargo | R13: Yes | S13: Expedited
... A1001: SHP1000 | B1001: Inbound | C1001: Gujarat | D1001: Surat | E1001: Semi-Processed Yarn | F1001: 14.07 | G1001: 2025-10-09 | H1001: 2025-10-12 | I1001: 2025-10-17 | J1001: 2025-10-11 23:00:00 | K1001: 2025-10-22 09:36:00 | L1001: 5.4 | M1001: 1 | N1001: 5637.64 | O1001: 4671.39 | P1001: 887.07 | Q1001: TCI Express | R1001: Yes | S1001: Returned
